Workbook
Name Slicer_Critical_Skill: #N/A
Name Slicer_Department: #N/A
Name Slicer_Exit_Reason: #N/A
Name Slicer_Job_Satisfaction: #N/A
Name Slicer_Salary_Grade: #N/A

Sheet Dashboard

Sheet Sheet2
A3: Row Labels | B3: Sum of Age | C3: Sum of KPI Achievement % | D3: Sum of Training Hours | E3: Sum of Goal Completion %
A4: Data Analyst | B4: 281 | C4: 641 | D4: 223 | E4: 695
A5: DevOps Engineer | B5: 392 | C5: 845 | D5: 405 | E5: 796
A6: QA Engineer | B6: 127 | C6: 339 | D6: 112 | E6: 309
A7: Software Engineer | B7: 179 | C7: 392 | D7: 164 | E7: 428
A8: System Administrator | B8: 103 | C8: 256 | D8: 80 | E8: 231
A9: UI/UX Designer | B9: 478 | C9: 873 | D9: 353 | E9: 838
A10: Grand Total | B10: 1560 | C10: 3346 | D10: 1337 | E10: 3297
A23: Row Labels | B23: Sum of Work-Life Balance | C23: Sum of Years at Company | D23: Sum of Monthly Salary | E23: Sum of Job Satisfaction
A24: Administration | B24: 14 | C24: 28.5 | D24: 575248 | E24: 14
A25: Customer Support | B25: 18 | C25: 30.3 | D25: 550568 | E25: 14
A26: Finance | B26: 22 | C26: 39.8 | D26: 566336 | E26: 14
A27: HR | B27: 34 | C27: 39.1 | D27: 998159 | E27: 24
A28: IT | B28: 36 | C28: 45.8 | D28: 807176 | E28: 22
A29: Logistics | B29: 27 | C29: 51.6 | D29: 863148 | E29: 20
A30: Marketing | B30: 32 | C30: 47.5 | D30: 821658 | E30: 22
A31: Operations | B31: 27 | C31: 32.3 | D31: 716814 | E31: 22
A32: R&D | B32: 42 | C32: 69.3 | D32: 935603 | E32: 26
A33: Sales | B33: 40 | C33: 38.7 | D33: 861583 | E33: 20
A34: Grand Total | B34: 292 | C34: 422.9 | D34: 7696293 | E34: 198
A40: Row Labels | B40: Sum of Job Satisfaction | C40: Sum of Years at Company | D40: Sum of Work-Life Balance
A41: No | B41: 9 | C41: 8.9 | D41: 7
A42: Exited | B42: 9 | C42: 8.9 | D42: 7
A43: Yes | B43: 13 | C43: 16.2 | D43: 7
A44: Exited | B44: 13 | C44: 16.2 | D44: 7
A45: Grand Total | B45: 22 | C45: 25.1 | D45: 14
A61: Row Labels | B61: Sum of Experience (Years) | C61: Sum of Monthly Salary | D61: Sum of Total Compensation | E61: Sum of Last Increment %
A62: Account Manager | B62: 8.3 | C62: 196517 | D62: 2637553 | E62: 8.1
A63: Admin Executive | B63: 4.6 | C63: 89524 | D63: 1137671 | E63: 6.8
A64: Operations Executive | B64: 13.5 | C64: 124064 | D64: 1699548 | E64: 22.2
A65: System Administrator | B65: 11.4 | C65: 142773 | D65: 1990546 | E65: 18.7
A66: Training Specialist | B66: 21.2 | C66: 390856 | D66: 5198643 | E66: 41.5
A67: Grand Total | B67: 59 | C67: 943734 | D67: 12663961 | E67: 97.3
A80: Row Labels | B80: Count of Training Need
A81: AI / ML | B81: 18
A82: High | B82: 10
A83: Low | B83: 3
A84: Medium | B84: 5
A85: Grand Total | B85: 18

Sheet M1_Performance
A1: Employee ID | B1: Employee Name | C1: Department | D1: Job Role | E1: Gender | F1: Age | G1: Performance Score | H1: Productivity % | I1: KPI Achievement % | J1: Goal Completion % | K1: Training Hours | L1: Review Rating | M1: Review Year
A2: EMP00001 | B2: Ram Gupta | C2: HR | D2: HR Executive | E2: Female | F2: 36 | G2: 3.44 | H2: 85 | I2: 66 | J2: 68 | K2: 46 | L2: Very Good | M2: 2026
A3: EMP00002 | B3: Rohan Rao | C3: R&D | D3: Research Analyst | E3: Female | F3: 23 | G3: 4.8 | H3: 74 | I3: 78 | J3: 77 | K3: 30 | L3: Average | M3: 2026
A4: EMP00003 | B4: Yash Upadhyay | C4: R&D | D4: Research Analyst | E4: Male | F4: 55 | G4: 2.97 | H4: 100 | I4: 91 | J4: 98 | K4: 32 | L4: Needs Improvement | M4: 2026
A5: EMP00004 | B5: Aryan Joshi | C5: Sales | D5: Sales Executive | E5: Male | F5: 48 | G5: 2.34 | H5: 77 | I5: 67 | J5: 79 | K5: 12 | L5: Needs Improvement | M5: 2024
A6: EMP00005 | B6: Karan Kapoor | C6: Operations | D6: Operations Executive | E6: Male | F6: 45 | G6: 3.81 | H6: 77 | I6: 64 | J6: 99 | K6: 11 | L6: Good | M6: 2024
A7: EMP00006 | B7: Vikram Malhotra | C7: Logistics | D7: Warehouse Manager | E7: Male | F7: 50 | G7: 4.67 | H7: 87 | I7: 85 | J7: 90 | K7: 11 | L7: Average | M7: 2026
A8: EMP00007 | B8: Rinku Verma | C8: HR | D8: Payroll Executive | E8: Female | F8: 44 | G8: 4.51 | H8: 79 | I8: 91 | J8: 78 | K8: 15 | L8: Average | M8: 2025
A9: EMP00008 | B9: Karan Gupta | C9: IT | D9: System Administrator | E9: Male | F9: 39 | G9: 3.98 | H9: 100 | I9: 78 | J9: 65 | K9: 11 | L9: Average | M9: 2026
A10: EMP00009 | B10: Nisha Joshi | C10: Customer Support | D10: Customer Success Analyst | E10: Female | F10: 44 | G10: 4.74 | H10: 92 | I10: 79 | J10: 80 | K10: 15 | L10: Good | M10: 2026
A11: EMP00010 | B11: Yash Malhotra | C11: Sales | D11: Sales Executive | E11: Male | F11: 55 | G11: 2.39 | H11: 73 | I11: 81 | J11: 94 | K11: 14 | L11: Needs Improvement | M11: 2026
A12: EMP00011 | B12: Arun Singh | C12: Sales | D12: Sales Analyst | E12: Male | F12: 41 | G12: 3.53 | H12: 83 | I12: 61 | J12: 76 | K12: 21 | L12: Needs Improvement | M12: 2024
A13: EMP00012 | B13: Neha Tiwari | C13: Operations | D13: Operations Analyst | E13: Female | F13: 25 | G13: 4.1 | H13: 62 | I13: 98 | J13: 87 | K13: 35 | L13: Excellent | M13: 2024
... A501: EMP00500 | B501: Diya Dwivedi | C501: R&D | D501: Research Analyst | E501: Male | F501: 51 | G501: 2.27 | H501: 68 | I501: 80 | J501: 100 | K501: 35 | L501: Excellent | M501: 2025

Sheet M2_Attrition
A1: Employee ID | B1: Employee Name | C1: Department | D1: Job Role | E1: Gender | F1: Age | G1: Monthly Salary | H1: Years at Company | I1: Job Satisfaction | J1: Work-Life Balance | K1: Overtime | L1: Attrition Status | M1: Exit Reason | N1: Exit Date
A2: EMP00001 | B2: Ram Gupta | C2: HR | D2: HR Executive | E2: Female | F2: 36 | G2: 46289 | H2: 5.2 | I2: 2 | J2: 2 | K2: Yes | L2: Active
A3: EMP00002 | B3: Rohan Rao | C3: R&D | D3: Research Analyst | E3: Female | F3: 23 | G3: 40280 | H3: 7.4 | I3: 5 | J3: 4 | K3: Yes | L3: Active
A4: EMP00003 | B4: Yash Upadhyay | C4: R&D | D4: Research Analyst | E4: Male | F4: 55 | G4: 56893 | H4: 3 | I4: 4 | J4: 2 | K4: No | L4: Active
A5: EMP00004 | B5: Aryan Joshi | C5: Sales | D5: Sales Executive | E5: Male | F5: 48 | G5: 64421 | H5: 3.9 | I5: 2 | J5: 1 | K5: Yes | L5: Active
A6: EMP00005 | B6: Karan Kapoor | C6: Operations | D6: Operations Executive | E6: Male | F6: 45 | G6: 75052 | H6: 6.7 | I6: 5 | J6: 4 | K6: Yes | L6: Exited | M6: Better Opportunity | N6: 45469
A7: EMP00006 | B7: Vikram Malhotra | C7: Logistics | D7: Warehouse Manager | E7: Male | F7: 50 | G7: 44361 | H7: 1.7 | I7: 4 | J7: 1 | K7: No | L7: Active
A8: EMP00007 | B8: Rinku Verma | C8: HR | D8: Payroll Executive | E8: Female | F8: 44 | G8: 53203 | H8: 1.3 | I8: 5 | J8: 3 | K8: Yes | L8: Active
A9: EMP00008 | B9: Karan Gupta | C9: IT | D9: System Administrator | E9: Male | F9: 39 | G9: 58512 | H9: 6.9 | I9: 4 | J9: 3 | K9: No | L9: Active
A10: EMP00009 | B10: Nisha Joshi | C10: Customer Support | D10: Customer Success Analyst | E10: Female | F10: 44 | G10: 76520 | H10: 5.9 | I10: 5 | J10: 2 | K10: Yes | L10: Exited | M10: Career Growth | N10: 45302
A11: EMP00010 | B11: Yash Malhotra | C11: Sales | D11: Sales Executive | E11: Male | F11: 55 | G11: 49417 | H11: 5 | I11: 3 | J11: 3 | K11: No | L11: Active
A12: EMP00011 | B12: Arun Singh | C12: Sales | D12: Sales Analyst | E12: Male | F12: 41 | G12: 58021 | H12: 7.1 | I12: 4 | J12: 1 | K12: Yes | L12: Active
A13: EMP00012 | B13: Neha Tiwari | C13: Operations | D13: Operations Analyst | E13: Female | F13: 25 | G13: 102341 | H13: 5.4 | I13: 2 | J13: 5 | K13: Yes | L13: Active
A14: EMP00013 | B14: Aryan Rao | C14: Marketing | D14: Brand Manager | E14: Female | F14: 50 | G14: 62718 | H14: 6.1 | I14: 2 | J14: 3 | K14: Yes | L14: Active
A15: EMP00014 | B15: Ishita Kumar | C15: R&D | D15: Product Researcher | E15: Female | F15: 58 | G15: 75447 | H15: 3.3 | I15: 1 | J15: 2 | K15: No | L15: Active
A16: EMP00015 | B16: Anshul Patel | C16: R&D | D16: Innovation Analyst | E16: Male | F16: 24 | G16: 48033 | H16: 6.5 | I16: 4 | J16: 3 | K16: No | L16: Active
A17: EMP00016 | B17: Rahul Khan | C17: Customer Support | D17: Support Executive | E17: Female | F17: 45 | G17: 89348 | H17: 1.1 | I17: 5 | J17: 3 | K17: No | L17: Active
A18: EMP00017 | B18: Vihaan Gupta | C18: R&D | D18: Research Analyst | E18: Male | F18: 55 | G18: 112012 | H18: 4.8 | I18: 5 | J18: 4 | K18: Yes | L18: Active
A19: EMP00018 | B19: Neha Khan | C19: Sales | D19: Account Manager | E19: Male | F19: 50 | G19: 122646 | H19: 7.7 | I19: 5 | J19: 2 | K19: Yes | L19: Active
A20: EMP00019 | B20: Rohan Kumar | C20: R&D | D20: Research Engineer | E20: Male | F20: 40 | G20: 107818 | H20: 2.1 | I20: 3 | J20: 5 | K20: No | L20: Active
A21: EMP00020 | B21: Ananya Kapoor | C21: Operations | D21: Operations Manager | E21: Male | F21: 41 | G21: 30552 | H21: 2.3 | I21: 3 | J21: 4 | K21: No | L21: Active
A22: EMP00021 | B22: Arjun Sethi | C22: Sales | D22: Sales Manager | E22: Male | F22: 36 | G22: 38322 | H22: 1.4 | I22: 1 | J22: 2 | K22: No | L22: Exited | M22: Relocation | N22: 45501
A23: EMP00022 | B23: Diya Khan | C23: HR | D23: Payroll Executive | E23: Male | F23: 29 | G23: 100063 | H23: 2.4 | I23: 2 | J23: 2 | K23: No | L23: Active
A24: EMP00023 | B24: Meera Malhotra | C24: R&D | D24: Innovation Analyst | E24: Male | F24: 55 | G24: 121447 | H24: 5.5 | I24: 2 | J24: 1 | K24: Yes | L24: Active
A25: EMP00024 | B25: Arjun Tiwari | C25: Operations | D25: Operations Analyst | E25: Female | F25: 28 | G25: 57451 | H25: 5 | I25: 4 | J25: 3 | K25: Yes | L25: Active
A26: EMP00025 | B26: Arjun Singh | C26: IT | D26: UI/UX Designer | E26: Male | F26: 58 | G26: 28942 | H26: 5.3 | I26: 2 | J26: 1 | K26: Yes | L26: Active
A27: EMP00026 | B27: Ishita Khan | C27: Marketing | D27: Marketing Executive | E27: Male | F27: 42 | G27: 95391 | H27: 7 | I27: 4 | J27: 5 | K27: No | L27: Active
A28: EMP00027 | B28: Ishita Sethi | C28: Administration | D28: Office Manager | E28: Male | F28: 57 | G28: 89953 | H28: 1.3 | I28: 4 | J28: 5 | K28: Yes | L28: Exited | M28: Work Pressure | N28: 46102
A29: EMP00028 | B29: Sara Nair | C29: Customer Support | D29: Support Manager | E29: Male | F29: 27 | G29: 74438 | H29: 2.9 | I29: 2 | J29: 5 | K29: No | L29: Active
A30: EMP00029 | B30: Vihaan Gupta | C30: Administration | D30: Admin Executive | E30: Male | F30: 24 | G30: 123448 | H30: 3.2 | I30: 5 | J30: 1 | K30: Yes | L30: Active
A31: EMP00030 | B31: Sara Patel | C31: Marketing | D31: SEO Specialist | E31: Male | F31: 55 | G31: 46373 | H31: 2.7 | I31: 1 | J31: 4 | K31: No | L31: Active
A32: EMP00031 | B32: Ananya Singh | C32: Sales | D32: Account Manager | E32: Male | F32: 25 | G32: 100132 | H32: 2.8 | I32: 1 | J32: 4 | K32: No | L32: Active
A33: EMP00032 | B33: Pooja Sethi | C33: R&D | D33: Research Analyst | E33: Male | F33: 36 | G33: 81269 | H33: 5.9 | I33: 1 | J33: 3 | K33: Yes | L33: Active
A34: EMP00033 | B34: Aditya Khan | C34: Marketing | D34: Brand Manager | E34: Male | F34: 31 | G34: 28282 | H34: 3.5 | I34: 1 | J34: 2 | K34: Yes | L34: Active
A35: EMP00034 | B35: Rohan Mehta | C35: Administration | D35: Admin Assistant | E35: Female | F35: 56 | G35: 48289 | H35: 2.3 | I35: 3 | J35: 1 | K35: Yes | L35: Active
A36: EMP00035 | B36: Aman Sethi | C36: Marketing | D36: Marketing Executive | E36: Male | F36: 41 | G36: 34572 | H36: 7.1 | I36: 5 | J36: 5 | K36: No | L36: Active
A37: EMP00036 | B37: Arjun Dwivedi | C37: R&D | D37: Research Engineer | E37: Male | F37: 53 | G37: 52356 | H37: 6.8 | I37: 3 | J37: 2 | K37: No | L37: Active
A38: EMP00037 | B38: Aman Dwivedi | C38: HR | D38: Recruiter | E38: Female | F38: 28 | G38: 60271 | H38: 1.4 | I38: 2 | J38: 2 | K38: Yes | L38: Active
A39: EMP00038 | B39: Rahul Tiwari | C39: IT | D39: UI/UX Designer | E39: Male | F39: 47 | G39: 102085 | H39: 1.2 | I39: 2 | J39: 5 | K39: Yes | L39: Exited | M39: Compensation | N39: 45308
A40: EMP00039 | B40: Aryan Mehta | C40: Sales | D40: Sales Manager | E40: Female | F40: 36 | G40: 79876 | H40: 4.8 | I40: 3 | J40: 4 | K40: Yes | L40: Active
...

Sheet M3_Recruitment
A1: Application ID | B1: Application Date | C1: Candidate Name | D1: Department | E1: Job Role | F1: Source | G1: Experience (Years) | H1: Education | I1: Screening Score | J1: Interview Score | K1: Stage | L1: Offer Status | M1: Days to Hire | N1: Recruiter
A2: APP00001 | B2: 46052 | C2: Rohan Joshi | D2: Logistics | E2: Transport Coordinator | F2: LinkedIn | G2: 7 | H2: MBA | I2: 67 | J2: 77 | K2: Hired | L2: Accepted | M2: 43 | N2: Recruiter A
A3: APP00002 | B3: 45986 | C3: Rohan Khan | D3: Administration | E3: Admin Executive | F3: Company Website | G3: 0 | H3: MCA | I3: 66 | J3: 74 | K3: Applied | L3: N/A | N3: Recruiter E
A4: APP00003 | B4: 46014 | C4: Riya Kapoor | D4: HR | E4: Payroll Executive | F4: LinkedIn | G4: 6 | H4: Diploma | I4: 65 | J4: 68 | K4: Offered | L4: Pending | N4: Recruiter B
A5: APP00004 | B5: 46265 | C5: Diya Malhotra | D5: Marketing | E5: Digital Marketing Analyst | F5: Employee Referral | G5: 12 | H5: MCA | I5: 93 | J5: 72 | K5: Applied | L5: N/A | N5: Recruiter B
A6: APP00005 | B6: 46151 | C6: Vihaan Mishra | D6: HR | E6: HR Manager | F6: Consultancy | G6: 5 | H6: Diploma | I6: 80 | J6: 42 | K6: Applied | L6: N/A | N6: Recruiter D
A7: APP00006 | B7: 46277 | C7: Rohan Sharma | D7: Customer Support | E7: Service Executive | F7: LinkedIn | G7: 3 | H7: Other | I7: 45 | J7: 92 | K7: Rejected | L7: N/A | N7: Recruiter E
A8: APP00007 | B8: 45819 | C8: Aman Mishra | D8: Operations | E8: Operations Manager | F8: Consultancy | G8: 7 | H8: MCA | I8: 56 | J8: 70 | K8: Hired | L8: Accepted | M8: 37 | N8: Recruiter B
A9: APP00008 | B9: 45729 | C9: Diya Tiwari | D9: Sales | E9: Business Development Executive | F9: LinkedIn | G9: 10 | H9: Other | I9: 68 | J9: 91 | K9: Hired | L9: Accepted | M9: 13 | N9: Recruiter E
A10: APP00009 | B10: 46094 | C10: Yash Joshi | D10: Operations | E10: Process Analyst | F10: Job Portal | G10: 1 | H10: B.Tech | I10: 60 | J10: 40 | K10: Rejected | L10: N/A | N10: Recruiter E
A11: APP00010 | B11: 45666 | C11: Riya Patel | D11: Administration | E11: Office Manager | F11: Employee Referral | G11: 10 | H11: Other | I11: 74 | J11: 88 | K11: Rejected | L11: N/A | N11: Recruiter D
A12: APP00011 | B12: 45776 | C12: Vihaan Kumar | D12: Administration | E12: Facility Coordinator | F12: Social Media | G12: 1 | H12: MCA | I12: 93 | J12: 72 | K12: Screened | L12: N/A | N12: Recruiter D
A13: APP00012 | B13: 45861 | C13: Yash Verma | D13: R&D | E13: Innovation Analyst | F13: LinkedIn | G13: 0 | H13: Graduate | I13: 94 | J13: 78 | K13: Applied | L13: N/A | N13: Recruiter A
A14: APP00013 | B14: 45802 | C14: Rohan Singh | D14: Finance | E14: Finance Manager | F14: Company Website | G14: 3 | H14: MCA | I14: 63 | J14: 83 | K14: Screened | L14: N/A | N14: Recruiter D
A15: APP00014 | B15: 45754 | C15: Rinku Nair | D15: Administration | E15: Facility Coordinator | F15: Job Portal | G15: 12 | H15: MCA | I15: 84 | J15: 93 | K15: Rejected | L15: N/A | N15: Recruiter E
A16: APP00015 | B16: 45768 | C16: Nisha Malhotra | D16: Logistics | E16: Transport Coordinator | F16: Employee Referral | G16: 6 | H16: Other | I16: 68 | J16: 85 | K16: Interviewed | L16: N/A | N16: Recruiter D
A17: APP00016 | B17: 45699 | C17: Rahul Rao | D17: Customer Support | E17: Customer Success Analyst | F17: LinkedIn | G17: 9 | H17: Diploma | I17: 84 | J17: 86 | K17: Offered | L17: Pending | N17: Recruiter C
A18: APP00017 | B18: 46033 | C18: Meera Kumar | D18: IT | E18: Software Engineer | F18: Social Media | G18: 2 | H18: MBA | I18: 55 | J18: 99 | K18: Rejected | L18: N/A | N18: Recruiter C
A19: APP00018 | B19: 45863 | C19: Aman Verma | D19: Marketing | E19: Brand Manager | F19: Consultancy | G19: 11 | H19: Diploma | I19: 56 | J19: 48 | K19: Rejected | L19: N/A | N19: Recruiter B
A20: APP00019 | B20: 46127 | C20: Govind Rao | D20: Logistics | E20: Logistics Executive | F20: Employee Referral | G20: 0 | H20: Graduate | I20: 68 | J20: 84 | K20: Screened | L20: N/A | N20: Recruiter A
A21: APP00020 | B21: 46258 | C21: Aditi Gupta | D21: Operations | E21: Operations Analyst | F21: Job Portal | G21: 1 | H21: Graduate | I21: 50 | J21: 98 | K21: Rejected | L21: N/A | N21: Recruiter D
... A28: APP00027 | B28: 45660 | C28: Ram Kumar | D28: Finance | E28: Finance Manager | F28: Job Portal | G28: 0 | H28: B.Tech | I28: 96 | J28: 42 | K28: Offered | L28: Pending | N28: Recruiter D
A29: APP00028 | B29: 45969 | C29: Arjun Upadhyay | D29: IT | E29: Software Engineer | F29: Job Portal | G29: 10 | H29: B.Tech | I29: 92 | J29: 64 | K29: Hired | L29: Accepted | M29: 30 | N29: Recruiter C
A30: APP00029 | B30: 45804 | C30: Rohan Singh | D30: Sales | E30: Sales Manager | F30: Social Media | G30: 7 | H30: MCA | I30: 52 | J30: 65 | K30: Rejected | L30: N/A | N30: Recruiter B
A31: APP00030 | B31: 46088 | C31: Lakhan Joshi | D31: Marketing | E31: Content Strategist | F31: Consultancy | G31: 10 | H31: Graduate | I31: 58 | J31: 64 | K31: Interviewed | L31: N/A | N31: Recruiter A
A32: APP00031 | B32: 45696 | C32: Aman Rao | D32: IT | E32: Software Engineer | F32: Job Portal | G32: 9 | H32: B.Tech | I32: 48 | J32: 73 | K32: Rejected | L32: N/A | N32: Recruiter D
A33: APP00032 | B33: 45661 | C33: Aditi Patel | D33: R&D | E33: Research Analyst | F33: Campus | G33: 12 | H33: MCA | I33: 64 | J33: 94 | K33: Rejected | L33: N/A | N33: Recruiter B
A34: APP00033 | B34: 45724 | C34: Lakhan Patel | D34: Operations | E34: Process Analyst | F34: Campus | G34: 5 | H34: MCA | I34: 79 | J34: 96 | K34: Rejected | L34: N/A | N34: Recruiter A
A35: APP00034 | B35: 45708 | C35: Sara Nair | D35: Logistics | E35: Supply Chain Analyst | F35: Job Portal | G35: 4 | H35: Post Graduate | I35: 90 | J35: 54 | K35: Offered | L35: Pending | N35: Recruiter D
A36: APP00035 | B36: 46204 | C36: Aryan Kumar | D36: Customer Support | E36: Support Manager | F36: Social Media | G36: 10 | H36: MCA | I36: 46 | J36: 72 | K36: Hired | L36: Accepted | M36: 15 | N36: Recruiter D
A37: APP00036 | B37: 46015 | C37: Kabir Das | D37: R&D | E37: Research Analyst | F37: Consultancy | G37: 12 | H37: Graduate | I37: 81 | J37: 59 | K37: Hired | L37: Accepted | M37: 54 | N37: Recruiter C
A38: APP00037 | B38: 45748 | C38: Rohan Rao | D38: Marketing | E38: Marketing Executive | F38: Job Portal | G38: 0 | H38: Other | I38: 67 | J38: 83 | K38: Interviewed | L38: N/A | N38: Recruiter E
A39: APP00038 | B39: 45865 | C39: Aryan Gupta | D39: Customer Support | E39: Service Executive | F39: Campus | G39: 9 | H39: B.Tech | I39: 73 | J39: 79 | K39: Interviewed | L39: N/A | N39: Recruiter A
A40: APP00039 | B40: 46090 | C40: Ram Kapoor | D40: Sales | E40: Sales Manager | F40: Social Media | G40: 9 | H40: Graduate | I40: 59 | J40: 70 | K40: Rejected | L40: N/A | N40: Recruiter A
A41: APP00040 | B41: 46095 | C41: Pooja Sethi | D41: Customer Support | E41: Service Executive | F41: Employee Referral | G41: 7 | H41: Other | I41: 89 | J41: 95 | K41: Applied | L41: N/A | N41: Recruiter B
A42: APP00041 | B42: 46076 | C42: Govind Kapoor | D42: R&D | E42: Research Engineer | F42: Job Portal | G42: 3 | H42: Graduate | I42: 72 | J42: 74 | K42: Interviewed | L42: N/A | N42: Recruiter D
A43: APP00042 | B43: 46069 | C43: Sara Nair | D43: Finance | E43: Payroll Analyst | F43: Employee Referral | G43: 2 | H43: B.Tech | I43: 82 | J43: 50 | K43: Applied | L43: N/A | N43: Recruiter E
A44: APP00043 | B44: 45857 | C44: Aditya Tiwari | D44: IT | E44: UI/UX Designer | F44: LinkedIn | G44: 7 | H44: Post Graduate | I44: 86 | J44: 65 | K44: Applied | L44: N/A | N44: Recruiter E
A45: APP00044 | B45: 46132 | C45: Vihaan Upadhyay | D45: Logistics | E45: Logistics Executive | F45: Campus | G45: 4 | H45: Graduate | I45: 82 | J45: 77 | K45: Applied | L45: N/A | N45: Recruiter B
A46: APP00045 | B46: 46146 | C46: Satyam Sethi | D46: Operations | E46: Process Analyst | F46: Employee Referral | G46: 7 | H46: Diploma | I46: 74 | J46: 49 | K46: Screened | L46: N/A | N46: Recruiter A
...

Sheet M4_Compensation
A1: Employee ID | B1: Employee Name | C1: Department | D1: Job Role | E1: Experience (Years) | F1: Monthly Salary | G1: Annual Salary | H1: Bonus % | I1: Annual Bonus | J1: Total Compensation | K1: Salary Grade | L1: Last Increment %
A2: EMP00001 | B2: Ram Gupta | C2: HR | D2: HR Executive | E2: 5.2 | F2: 46289 | G2: 555468 | H2: 9.5 | I2: 52769 | J2: 608237 | K2: G6 | L2: 13.5
A3: EMP00002 | B3: Rohan Rao | C3: R&D | D3: Research Analyst | E3: 7.4 | F3: 40280 | G3: 483360 | H3: 14.3 | I3: 69120 | J3: 552480 | K3: G4 | L3: 4.7
A4: EMP00003 | B4: Yash Upadhyay | C4: R&D | D4: Research Analyst | E4: 3 | F4: 56893 | G4: 682716 | H4: 11.9 | I4: 81243 | J4: 763959 | K4: G2 | L4: 4.8
A5: EMP00004 | B5: Aryan Joshi | C5: Sales | D5: Sales Executive | E5: 3.9 | F5: 64421 | G5: 773052 | H5: 14.9 | I5: 115185 | J5: 888237 | K5: G5 | L5: 12.4
A6: EMP00005 | B6: Karan Kapoor | C6: Operations | D6: Operations Executive | E6: 6.7 | F6: 75052 | G6: 900624 | H6: 14 | I6: 126087 | J6: 1026711 | K6: G2 | L6: 8.3
A7: EMP00006 | B7: Vikram Malhotra | C7: Logistics | D7: Warehouse Manager | E7: 1.7 | F7: 44361 | G7: 532332 | H7: 6.4 | I7: 34069 | J7: 566401 | K7: G1 | L7: 11.7
A8: EMP00007 | B8: Rinku Verma | C8: HR | D8: Payroll Executive | E8: 1.3 | F8: 53203 | G8: 638436 | H8: 11.7 | I8: 74697 | J8: 713133 | K8: G3 | L8: 5.4
A9: EMP00008 | B9: Karan Gupta | C9: IT | D9: System Administrator | E9: 6.9 | F9: 58512 | G9: 702144 | H9: 14 | I9: 98300 | J9: 800444 | K9: G2 | L9: 8.3
A10: EMP00009 | B10: Nisha Joshi | C10: Customer Support | D10: Customer Success Analyst | E10: 5.9 | F10: 76520 | G10: 918240 | H10: 5.9 | I10: 54176 | J10: 972416 | K10: G1 | L10: 8.2
A11: EMP00010 | B11: Yash Malhotra | C11: Sales | D11: Sales Executive | E11: 5 | F11: 49417 | G11: 593004 | H11: 10.5 | I11: 62265 | J11: 655269 | K11: G3 | L11: 13.6
A12: EMP00011 | B12: Arun Singh | C12: Sales | D12: Sales Analyst | E12: 7.1 | F12: 58021 | G12: 696252 | H12: 13.1 | I12: 91209 | J12: 787461 | K12: G3 | L12: 14.3
A13: EMP00012 | B13: Neha Tiwari | C13: Operations | D13: Operations Analyst | E13: 5.4 | F13: 102341 | G13: 1228092 | H13: 11 | I13: 135090 | J13: 1363182 | K13: G1 | L13: 5.9
... A501: EMP00500 | B501: Diya Dwivedi | C501: R&D | D501: Research Analyst | E501: 6.3 | F501: 112852 | G501: 1354224 | H501: 13.1 | I501: 177403 | J501: 1531627 | K501: G3 | L501: 14.3

Sheet M5_Workforce_Planning
A1: Plan ID | B1: Year | C1: Department | D1: Job Role | E1: Current Headcount | F1: Required Headcount | G1: Projected Demand | H1: Current Gap | I1: Projected Gap | J1: Critical Skill | K1: Skill Gap % | L1: Hiring Priority | M1: Attrition Forecast % | N1: Training Need
A2: PLAN0001 | B2: 2029 | C2: R&D | D2: Innovation Analyst | E2: 22 | F2: 24 | G2: 32 | H2: 2 | I2: 10 | J2: Digital Marketing | K2: 41 | L2: High | M2: 17.3 | N2: Medium
A3: PLAN0002 | B3: 2026 | C3: Sales | D3: Sales Analyst | E3: 68 | F3: 81 | G3: 101 | H3: 13 | I3: 33 | J3: Cloud Computing | K3: 29 | L3: High | M3: 4.5 | N3: Critical
A4: PLAN0003 | B4: 2028 | C4: Finance | D4: Finance Manager | E4: 51 | F4: 55 | G4: 57 | H4: 4 | I4: 6 | J4: Sales Strategy | K4: 12 | L4: High | M4: 11.2 | N4: Medium
A5: PLAN0004 | B5: 2026 | C5: Customer Support | D5: Customer Success Analyst | E5: 22 | F5: 25 | G5: 39 | H5: 3 | I5: 17 | J5: Digital Marketing | K5: 12 | L5: Low | M5: 6.9 | N5: Critical
A6: PLAN0005 | B6: 2026 | C6: Customer Support | D6: Customer Success Analyst | E6: 58 | F6: 67 | G6: 84 | H6: 9 | I6: 26 | J6: Project Management | K6: 21 | L6: High | M6: 12.5 | N6: Low
A7: PLAN0006 | B7: 2027 | C7: IT | D7: Data Analyst | E7: 61 | F7: 67 | G7: 85 | H7: 6 | I7: 24 | J7: Digital Marketing | K7: 33 | L7: Medium | M7: 8.4 | N7: Critical
A8: PLAN0007 | B8: 2030 | C8: HR | D8: Recruiter | E8: 15 | F8: 18 | G8: 27 | H8: 3 | I8: 12 | J8: Sales Strategy | K8: 43 | L8: Medium | M8: 12.6 | N8: High
A9: PLAN0008 | B9: 2027 | C9: HR | D9: Training Specialist | E9: 50 | F9: 63 | G9: 67 | H9: 13 | I9: 17 | J9: Cloud Computing | K9: 12 | L9: Low | M9: 17.7 | N9: Low
A10: PLAN0009 | B10: 2026 | C10: Marketing | D10: Digital Marketing Analyst | E10: 53 | F10: 67 | G10: 74 | H10: 14 | I10: 21 | J10: Cyber Security | K10: 42 | L10: Low | M10: 5.4 | N10: Critical
A11: PLAN0010 | B11: 2026 | C11: Customer Support | D11: Service Executive | E11: 27 | F11: 30 | G11: 30 | H11: 3 | I11: 3 | J11: Cloud Computing | K11: 36 | L11: High | M11: 17.2 | N11: Low
A12: PLAN0011 | B12: 2028 | C12: Marketing | D12: SEO Specialist | E12: 57 | F12: 68 | G12: 84 | H12: 11 | I12: 27 | J12: Communication | K12: 42 | L12: Medium | M12: 12.1 | N12: Critical
A13: PLAN0012 | B13: 2028 | C13: R&D | D13: Research Engineer | E13: 59 | F13: 72 | G13: 87 | H13: 13 | I13: 28 | J13: Sales Strategy | K13: 22 | L13: High | M13: 5.5 | N13: High
... A301: PLAN0300 | B301: 2027 | C301: Finance | D301: Accountant | E301: 29 | F301: 30 | G301: 43 | H301: 1 | I301: 14 | J301: Data Analytics | K301: 6 | L301: Low | M301: 13.7 | N301: Medium

Sheet Dashboard_Data
A1: Dashboard helper calculations — source module edits drive these formulas.
A3: Department | B3: Avg Performance | D3: Rating | E3: Count | G3: Top Employee | H3: Department | I3: Score
A4: IT | B4: =IFERROR(AVERAGEIF(M1_Performance!C:C,A4,M1_Performance!G:G),0) -> 3.7145 | D4: Excellent | E4: =COUNTIF(M1_Performance!L:L,D4) -> 98 | G4: =INDEX(M1_Performance!B:B,MATCH(I4,M1_Performance!G:G,0)) -> Divyansh Joshi | H4: =INDEX(M1_Performance!C:C,MATCH(I4,M1_Performance!G:G,0)) -> Administration | I4: =LARGE(M1_Performance!G:G,1) -> 5
A5: HR | B5: =IFERROR(AVERAGEIF(M1_Performance!C:C,A5,M1_Performance!G:G),0) -> 3.6378333 | D5: Very Good | E5: =COUNTIF(M1_Performance!L:L,D5) -> 103 | G5: =INDEX(M1_Performance!B:B,MATCH(I5,M1_Performance!G:G,0)) -> Ananya Singh | H5: =INDEX(M1_Performance!C:C,MATCH(I5,M1_Performance!G:G,0)) -> Sales | I5: =LARGE(M1_Performance!G:G,2) -> 4.99
A6: Finance | B6: =IFERROR(AVERAGEIF(M1_Performance!C:C,A6,M1_Performance!G:G),0) -> 3.5989362 | D6: Good | E6: =COUNTIF(M1_Performance!L:L,D6) -> 109 | G6: =INDEX(M1_Performance!B:B,MATCH(I6,M1_Performance!G:G,0)) -> Ananya Singh | H6: =INDEX(M1_Performance!C:C,MATCH(I6,M1_Performance!G:G,0)) -> Sales | I6: =LARGE(M1_Performance!G:G,3) -> 4.99
A7: Sales | B7: =IFERROR(AVERAGEIF(M1_Performance!C:C,A7,M1_Performance!G:G),0) -> 3.4242 | D7: Average | E7: =COUNTIF(M1_Performance!L:L,D7) -> 99 | G7: =INDEX(M1_Performance!B:B,MATCH(I7,M1_Performance!G:G,0)) -> Ananya Singh | H7: =INDEX(M1_Performance!C:C,MATCH(I7,M1_Performance!G:G,0)) -> Sales | I7: =LARGE(M1_Performance!G:G,4) -> 4.99
A8: Marketing | B8: =IFERROR(AVERAGEIF(M1_Performance!C:C,A8,M1_Performance!G:G),0) -> 3.4623913 | D8: Needs Improvement | E8: =COUNTIF(M1_Performance!L:L,D8) -> 91 | G8: =INDEX(M1_Performance!B:B,MATCH(I8,M1_Performance!G:G,0)) -> Aarav Gupta | H8: =INDEX(M1_Performance!C:C,MATCH(I8,M1_Performance!G:G,0)) -> Sales | I8: =LARGE(M1_Performance!G:G,5) -> 4.97
A9: Operations | B9: =IFERROR(AVERAGEIF(M1_Performance!C:C,A9,M1_Performance!G:G),0) -> 3.6955102
A10: R&D | B10: =IFERROR(AVERAGEIF(M1_Performance!C:C,A10,M1_Performance!G:G),0) -> 3.6291803
A11: Administration | B11: =IFERROR(AVERAGEIF(M1_Performance!C:C,A11,M1_Performance!G:G),0) -> 3.5964151
A12: Logistics | B12: =IFERROR(AVERAGEIF(M1_Performance!C:C,A12,M1_Performance!G:G),0) -> 3.6370213
A13: Department | B13: Attrition Rate | D13: Status | E13: Count | G13: Risk Employee | H13: Department | I13: Risk
A14: IT | B14: =IFERROR(COUNTIFS(M2_Attrition!C:C,A14,M2_Attrition!L:L,"Exited")/COUNTIF(M2_Attrition!C:C,A14),0) -> 0.125 | D14: Active | E14: =COUNTIF(M2_Attrition!L:L,D14) -> 451 | G14: =INDEX(M2_Attrition!B:B,MATCH(J14,M2_Attrition!I:I,0)) -> Ishita Kumar | H14: =INDEX(M2_Attrition!C:C,MATCH(J14,M2_Attrition!I:I,0)) -> R&D | I14: =IF(J14<=2,"High",IF(J14<=3,"Medium","Low")) -> High | J14: =SMALL(M2_Attrition!I:I,1) -> 1
A15: HR | B15: =IFERROR(COUNTIFS(M2_Attrition!C:C,A15,M2_Attrition!L:L,"Exited")/COUNTIF(M2_Attrition!C:C,A15),0) -> 0.1 | D15: Exited | E15: =COUNTIF(M2_Attrition!L:L,D15) -> 49 | G15: =INDEX(M2_Attrition!B:B,MATCH(J15,M2_Attrition!I:I,0)) -> Ishita Kumar | H15: =INDEX(M2_Attrition!C:C,MATCH(J15,M2_Attrition!I:I,0)) -> R&D | I15: =IF(J15<=2,"High",IF(J15<=3,"Medium","Low")) -> High | J15: =SMALL(M2_Attrition!I:I,2) -> 1
A16: Finance | B16: =IFERROR(COUNTIFS(M2_Attrition!C:C,A16,M2_Attrition!L:L,"Exited")/COUNTIF(M2_Attrition!C:C,A16),0) -> 0.12765957 | G16: =INDEX(M2_Attrition!B:B,MATCH(J16,M2_Attrition!I:I,0)) -> Ishita Kumar | H16: =INDEX(M2_Attrition!C:C,MATCH(J16,M2_Attrition!I:I,0)) -> R&D | I16: =IF(J16<=2,"High",IF(J16<=3,"Medium","Low")) -> High | J16: =SMALL(M2_Attrition!I:I,3) -> 1
A17: Sales | B17: =IFERROR(COUNTIFS(M2_Attrition!C:C,A17,M2_Attrition!L:L,"Exited")/COUNTIF(M2_Attrition!C:C,A17),0) -> 0.04 | G17: =INDEX(M2_Attrition!B:B,MATCH(J17,M2_Attrition!I:I,0)) -> Ishita Kumar | H17: =INDEX(M2_Attrition!C:C,MATCH(J17,M2_Attrition!I:I,0)) -> R&D | I17: =IF(J17<=2,"High",IF(J17<=3,"Medium","Low")) -> High | J17: =SMALL(M2_Attrition!I:I,4) -> 1
A18: Marketing | B18: =IFERROR(COUNTIFS(M2_Attrition!C:C,A18,M2_Attrition!L:L,"Exited")/COUNTIF(M2_Attrition!C:C,A18),0) -> 0.086956522 | G18: =INDEX(M2_Attrition!B:B,MATCH(J18,M2_Attrition!I:I,0)) -> Ishita Kumar | H18: =INDEX(M2_Attrition!C:C,MATCH(J18,M2_Attrition!I:I,0)) -> R&D | I18: =IF(J18<=2,"High",IF(J18<=3,"Medium","Low")) -> High | J18: =SMALL(M2_Attrition!I:I,5) -> 1
A19: Operations | B19: =IFERROR(COUNTIFS(M2_Attrition!C:C,A19,M2_Attrition!L:L,"Exited")/COUNTIF(M2_Attrition!C:C,A19),0) -> 0.14285714
A20: R&D | B20: =IFERROR(COUNTIFS(M2_Attrition!C:C,A20,M2_Attrition!L:L,"Exited")/COUNTIF(M2_Attrition!C:C,A20),0) -> 0.06557377
A21: Administration | B21: =IFERROR(COUNTIFS(M2_Attrition!C:C,A21,M2_Attrition!L:L,"Exited")/COUNTIF(M2_Attrition!C:C,A21),0) -> 0.16981132
A22: Logistics | B22: =IFERROR(COUNTIFS(M2_Attrition!C:C,A22,M2_Attrition!L:L,"Exited")/COUNTIF(M2_Attrition!C:C,A22),0) -> 0.063829787
A23: Customer Support | B23: =IFERROR(COUNTIFS(M2_Attrition!C:C,A23,M2_Attrition!L:L,"Exited")/COUNTIF(M2_Attrition!C:C,A23),0) -> 0.063829787
A24: Source | B24: Hires | D24: Stage | E24: Applications | G24: Month | H24: Hires | J24: Department | K24: Avg Days
A25: Job Portal | B25: =COUNTIFS(M3_Recruitment!F:F,A25,M3_Recruitment!K:K,"Hired") -> 7 | D25: Applied | E25: =COUNTIF(M3_Recruitment!K:K,D25) -> 136 | G25: =DATE(YEAR(TODAY()),1,1) -> 46023 | H25: =COUNTIFS(M3_Recruitment!B:B,">="&G25,M3_Recruitment!B:B,"<"&EDATE(G25,1),M3_Recruitment!K:K,"Hired") -> 4 | J25: IT | K25: =IFERROR(AVERAGEIF(M3_Recruitment!D:D,J25,M3_Recruitment!M:M),0) -> 28
A26: Campus | B26: =COUNTIFS(M3_Recruitment!F:F,A26,M3_Recruitment!K:K,"Hired") -> 6 | D26: Screened | E26: =COUNTIF(M3_Recruitment!K:K,D26) -> 92 | G26: =DATE(YEAR(TODAY()),2,1) -> 46054 | H26: =COUNTIFS(M3_Recruitment!B:B,">="&G26,M3_Recruitment!B:B,"<"&EDATE(G26,1),M3_Recruitment!K:K,"Hired") -> 1 | J26: HR | K26: =IFERROR(AVERAGEIF(M3_Recruitment!D:D,J26,M3_Recruitment!M:M),0) -> 31.666667
A27: Employee Referral | B27: =COUNTIFS(M3_Recruitment!F:F,A27,M3_Recruitment!K:K,"Hired") -> 6 | D27: Interviewed | E27: =COUNTIF(M3_Recruitment!K:K,D27) -> 76 | G27: =DATE(YEAR(TODAY()),3,1) -> 46082 | H27: =COUNTIFS(M3_Recruitment!B:B,">="&G27,M3_Recruitment!B:B,"<"&EDATE(G27,1),M3_Recruitment!K:K,"Hired") -> 3 | J27: Finance | K27: =IFERROR(AVERAGEIF(M3_Recruitment!D:D,J27,M3_Recruitment!M:M),0) -> 26.333333
A28: Social Media | B28: =COUNTIFS(M3_Recruitment!F:F,A28,M3_Recruitment!K:K,"Hired") -> 9 | D28: Offered | E28: =COUNTIF(M3_Recruitment!K:K,D28) -> 47 | G28: =DATE(YEAR(TODAY()),4,1) -> 46113 | H28: =COUNTIFS(M3_Recruitment!B:B,">="&G28,M3_Recruitment!B:B,"<"&EDATE(G28,1),M3_Recruitment!K:K,"Hired") -> 2 | J28: Sales | K28: =IFERROR(AVERAGEIF(M3_Recruitment!D:D,J28,M3_Recruitment!M:M),0) -> 34
A29: LinkedIn | B29: =COUNTIFS(M3_Recruitment!F:F,A29,M3_Recruitment!K:K,"Hired") -> 3 | D29: Hired | E29: =COUNTIF(M3_Recruitment!K:K,D29) -> 42 | G29: =DATE(YEAR(TODAY()),5,1) -> 46143 | H29: =COUNTIFS(M3_Recruitment!B:B,">="&G29,M3_Recruitment!B:B,"<"&EDATE(G29,1),M3_Recruitment!K:K,"Hired") -> 3 | J29: Marketing | K29: =IFERROR(AVERAGEIF(M3_Recruitment!D:D,J29,M3_Recruitment!M:M),0) -> 40
A30: Company Website | B30: =COUNTIFS(M3_Recruitment!F:F,A30,M3_Recruitment!K:K,"Hired") -> 5 | D30: Rejected | E30: =COUNTIF(M3_Recruitment!K:K,D30) -> 107 | G30: =DATE(YEAR(TODAY()),6,1) -> 46174 | H30: =COUNTIFS(M3_Recruitment!B:B,">="&G30,M3_Recruitment!B:B,"<"&EDATE(G30,1),M3_Recruitment!K:K,"Hired") -> 3 | J30: Operations | K30: =IFERROR(AVERAGEIF(M3_Recruitment!D:D,J30,M3_Recruitment!M:M),0) -> 33.666667
A31: Consultancy | B31: =COUNTIFS(M3_Recruitment!F:F,A31,M3_Recruitment!K:K,"Hired") -> 6 | G31: =DATE(YEAR(TODAY()),7,1) -> 46204 | H31: =COUNTIFS(M3_Recruitment!B:B,">="&G31,M3_Recruitment!B:B,"<"&EDATE(G31,1),M3_Recruitment!K:K,"Hired") -> 3 | J31: R&D | K31: =IFERROR(AVERAGEIF(M3_Recruitment!D:D,J31,M3_Recruitment!M:M),0) -> 41.25
G32: =DATE(YEAR(TODAY()),8,1) -> 46235 | H32: =COUNTIFS(M3_Recruitment!B:B,">="&G32,M3_Recruitment!B:B,"<"&EDATE(G32,1),M3_Recruitment!K:K,"Hired") -> 1 | J32: Administration | K32: =IFERROR(AVERAGEIF(M3_Recruitment!D:D,J32,M3_Recruitment!M:M),0) -> 54
G33: =DATE(YEAR(TODAY()),9,1) -> 46266 | H33: =COUNTIFS(M3_Recruitment!B:B,">="&G33,M3_Recruitment!B:B,"<"&EDATE(G33,1),M3_Recruitment!K:K,"Hired") -> 1 | J33: Logistics | K33: =IFERROR(AVERAGEIF(M3_Recruitment!D:D,J33,M3_Recruitment!M:M),0) -> 40
G34: =DATE(YEAR(TODAY()),10,1) -> 46296 | H34: =COUNTIFS(M3_Recruitment!B:B,">="&G34,M3_Recruitment!B:B,"<"&EDATE(G34,1),M3_Recruitment!K:K,"Hired") -> 0 | J34: Customer Support | K34: =IFERROR(AVERAGEIF(M3_Recruitment!D:D,J34,M3_Recruitment!M:M),0) -> 27.25
G35: =DATE(YEAR(TODAY()),11,1) -> 46327 | H35: =COUNTIFS(M3_Recruitment!B:B,">="&G35,M3_Recruitment!B:B,"<"&EDATE(G35,1),M3_Recruitment!K:K,"Hired") -> 0
G36: =DATE(YEAR(TODAY()),12,1) -> 46357 | H36: =COUNTIFS(M3_Recruitment!B:B,">="&G36,M3_Recruitment!B:B,"<"&EDATE(G36,1),M3_Recruitment!K:K,"Hired") -> 0
A40: Salary Band | B40: Count | D40: Department | E40: Avg Compensation | G40: Year | H40: Avg Salary | J40: Top Paid | K40: Department | L40: Total Compensation
A41: < ₹30K | B41: =COUNTIFS(M4_Compensation!F:F,">=0",M4_Compensation!F:F,"<=29999") -> 11 | D41: IT | E41: =IFERROR(AVERAGEIF(M4_Compensation!C:C,D41,M4_Compensation!J:J),0) -> 1033209.6 | G41: 2022 | H41: =AVERAGE(M4_Compensation!F:F)*(1+(2022-2021)*0.04) -> 78919.221 | J41: =INDEX(M4_Compensation!B:B,MATCH(L41,M4_Compensation!J:J,0)) -> Yash Mishra | K41: =INDEX(M4_Compensation!C:C,MATCH(L41,M4_Compensation!J:J,0)) -> Sales | L41: =LARGE(M4_Compensation!J:J,1) -> 1730890
A42: ₹30K–₹50K | B42: =COUNTIFS(M4_Compensation!F:F,">=30000",M4_Compensation!F:F,"<=49999") -> 100 | D42: HR | E42: =IFERROR(AVERAGEIF(M4_Compensation!C:C,D42,M4_Compensation!J:J),0) -> 969716.08 | G42: 2023 | H42: =AVERAGE(M4_Compensation!F:F)*(1+(2023-2021)*0.04) -> 81954.575 | J42: =INDEX(M4_Compensation!B:B,MATCH(L42,M4_Compensation!J:J,0)) -> Vihaan Gupta | K42: =INDEX(M4_Compensation!C:C,MATCH(L42,M4_Compensation!J:J,0)) -> Administration | L42: =LARGE(M4_Compensation!J:J,2) -> 1719878
A43: ₹50K–₹80K | B43: =COUNTIFS(M4_Compensation!F:F,">=50000",M4_Compensation!F:F,"<=79999") -> 175 | D43: Finance | E43: =IFERROR(AVERAGEIF(M4_Compensation!C:C,D43,M4_Compensation!J:J),0) -> 965477.55 | G43: 2024 | H43: =AVERAGE(M4_Compensation!F:F)*(1+(2024-2021)*0.04) -> 84989.93 | J43: =INDEX(M4_Compensation!B:B,MATCH(L43,M4_Compensation!J:J,0)) -> Govind Mishra | K43: =INDEX(M4_Compensation!C:C,MATCH(L43,M4_Compensation!J:J,0)) -> Logistics | L43: =LARGE(M4_Compensation!J:J,3) -> 1708319
A44: ₹80K–₹1.2L | B44: =COUNTIFS(M4_Compensation!F:F,">=80000",M4_Compensation!F:F,"<=119999") -> 194 | D44: Sales | E44: =IFERROR(AVERAGEIF(M4_Compensation!C:C,D44,M4_Compensation!J:J),0) -> 1095747.1 | G44: 2025 | H44: =AVERAGE(M4_Compensation!F:F)*(1+(2025-2021)*0.04) -> 88025.285 | J44: =INDEX(M4_Compensation!B:B,MATCH(L44,M4_Compensation!J:J,0)) -> Neha Khan | K44: =INDEX(M4_Compensation!C:C,MATCH(L44,M4_Compensation!J:J,0)) -> Sales | L44: =LARGE(M4_Compensation!J:J,4) -> 1707232
...

Sheet KPI CARD TABLE
D4: KPI CARDS TABLE
D7: TOTAL EMPLOYEE | E7: =COUNTA(M1_Performance!B2:B501) -> 500
D8: ATTRITION RATE | E8: =COUNTIF(M2_Attrition!L2:L501, "Exited") / COUNTA(M2_Attrition!A2:A501)*100 -> 9.8
D9: AVG PERFORMANCE SCORE | E9: =AVERAGE(M1_Performance!G2:G501) -> 3.60552
D10: AVG TIME TO HIRE | E10: =AVERAGE(M3_Recruitment!M2:M501) -> 35.452381
D11: AVG SALARY | E11: =AVERAGE(M4_Compensation!G2:G501) -> 910606.39
D12: TOTAL PAYROLL | E12: =SUM(M4_Compensation!J2:J501) -> 506209895
D13: WORKFORCE GAP | E13: =SUM(M5_Workforce_Planning!F2:F301)-SUM(M5_Workforce_Planning!E2:E301) -> 1866
